<?xml version="1.0" ?>
<robot name="myrobot" xmlns:xacro="http://www.ros.org/wiki/xacro">

<xacro:include filename="$(find myrobot_description)/urdf/materials.xacro" />
<xacro:include filename="$(find myrobot_description)/urdf/myrobot.trans" />
<xacro:include filename="$(find myrobot_description)/urdf/myrobot.gazebo" />
<link name="base_link">
  <inertial>
    <origin xyz="0.004875894859860826 3.470672019936501e-05 0.05830848045551468" rpy="0 0 0"/>
    <mass value="2.3492712687314"/>
    <inertia ixx="0.008062" iyy="0.008576" izz="0.015068" ixy="-4e-06" iyz="-2e-06" ixz="-0.00039"/>
  </inertial>
  <visual>
    <origin xyz="0 0 0" rpy="0 0 0"/>
    <geometry>
      <mesh filename="package://myrobot_description/meshes/base_link.stl" scale="0.001 0.001 0.001"/>
    </geometry>
    <material name="silver"/>
  </visual>
  <collision>
    <origin xyz="0 0 0" rpy="0 0 0"/>
    <geometry>
      <mesh filename="package://myrobot_description/meshes/base_link.stl" scale="0.001 0.001 0.001"/>
    </geometry>
  </collision>
</link>

<link name="right_wheel_1">
  <inertial>
    <origin xyz="-1.3739009929736312e-17 -0.012499999999999997 0.0" rpy="0 0 0"/>
    <mass value="0.1826050729899067"/>
    <inertia ixx="0.000124" iyy="0.000228" izz="0.000124" ixy="0.0" iyz="0.0" ixz="-0.0"/>
  </inertial>
  <visual>
    <origin xyz="-0.0 0.1 -0.055" rpy="0 0 0"/>
    <geometry>
      <mesh filename="package://myrobot_description/meshes/right_wheel_1.stl" scale="0.001 0.001 0.001"/>
    </geometry>
    <material name="silver"/>
  </visual>
  <collision>
    <origin xyz="-0.0 0.1 -0.055" rpy="0 0 0"/>
    <geometry>
      <mesh filename="package://myrobot_description/meshes/right_wheel_1.stl" scale="0.001 0.001 0.001"/>
    </geometry>
  </collision>
</link>

<link name="left_wheel_1">
  <inertial>
    <origin xyz="-1.0061396160665481e-17 0.012499999999999997 0.0" rpy="0 0 0"/>
    <mass value="0.1826050729899067"/>
    <inertia ixx="0.000124" iyy="0.000228" izz="0.000124" ixy="0.0" iyz="-0.0" ixz="-0.0"/>
  </inertial>
  <visual>
    <origin xyz="-0.0 -0.1 -0.055" rpy="0 0 0"/>
    <geometry>
      <mesh filename="package://myrobot_description/meshes/left_wheel_1.stl" scale="0.001 0.001 0.001"/>
    </geometry>
    <material name="silver"/>
  </visual>
  <collision>
    <origin xyz="-0.0 -0.1 -0.055" rpy="0 0 0"/>
    <geometry>
      <mesh filename="package://myrobot_description/meshes/left_wheel_1.stl" scale="0.001 0.001 0.001"/>
    </geometry>
  </collision>
</link>

<link name="lidar_1">
  <inertial>
    <origin xyz="0.0 6.980641276188792e-18 0.009999999999999995" rpy="0 0 0"/>
    <mass value="0.639226140411222"/>
    <inertia ixx="0.000228" iyy="0.000228" izz="0.000414" ixy="0.0" iyz="0.0" ixz="-0.0"/>
  </inertial>
  <visual>
    <origin xyz="-0.05 -0.0 -0.115" rpy="0 0 0"/>
    <geometry>
      <mesh filename="package://myrobot_description/meshes/lidar_1.stl" scale="0.001 0.001 0.001"/>
    </geometry>
    <material name="silver"/>
  </visual>
  <collision>
    <origin xyz="-0.05 -0.0 -0.115" rpy="0 0 0"/>
    <geometry>
      <mesh filename="package://myrobot_description/meshes/lidar_1.stl" scale="0.001 0.001 0.001"/>
    </geometry>
  </collision>
</link>

<link name="right_ultrasonic_1">
  <inertial>
    <origin xyz="0.0 -1.6505022612522957e-07 0.010000000000000009" rpy="0 0 0"/>
    <mass value="0.12560000000000004"/>
    <inertia ixx="8e-06" iyy="2.1e-05" izz="2.1e-05" ixy="-0.0" iyz="-0.0" ixz="0.0"/>
  </inertial>
  <visual>
    <origin xyz="-0.07 0.080468 -0.09" rpy="0 0 0"/>
    <geometry>
      <mesh filename="package://myrobot_description/meshes/right_ultrasonic_1.stl" scale="0.001 0.001 0.001"/>
    </geometry>
    <material name="silver"/>
  </visual>Description: simulates IMU sensor. Measurements are computed by the ROS plugin, not by Gazebo. See usage snippet sample below for implementation.

<robot>
:
  <gazebo>
    <plugin name="imu_plugin" filename="libgazebo_ros_imu.so">
      <alwaysOn>true</alwaysOn>
      <bodyName>base_footprint</bodyName>
      <topicName>imu</topicName>
      <serviceName>imu_service</serviceName>
      <gaussianNoise>0.0</gaussianNoise>
      <updateRate>20.0</updateRate>
    </plugin>
  </gazebo>
</robot>

IMU sensor (GazeboRosImuSensor)

Description: simulates an Inertial Motion Unit sensor, the main differences from IMU (GazeboRosIMU) are: - inheritance from SensorPlugin instead of ModelPlugin, - measurements are given by gazebo ImuSensor instead of being computed by the ros plugin, - gravity is included in inertial measurements. - set initialOrientationAsReference to false to comply with REP 145.

  <gazebo reference="imu_link">
    <gravity>true</gravity>
    <sensor name="imu_sensor" type="imu">
      <always_on>true</always_on>
      <update_rate>100</update_rate>
      <visualize>true</visualize>
      <topic>__default_topic__</topic>
      <plugin filename="libgazebo_ros_imu_sensor.so" name="imu_plugin">
        <topicName>imu</topicName>
        <bodyName>imu_link</bodyName>
        <updateRateHZ>10.0</updateRateHZ>
        <gaussianNoise>0.0</gaussianNoise>
        <xyzOffset>0 0 0</xyzOffset>
        <rpyOffset>0 0 0</rpyOffset>
        <frameName>imu_link</frameName>
        <initialOrientationAsReference>false</initialOrientationAsReference>
      </plugin>
      <pose>0 0 0 0 0 0</pose>
    </sensor>
  </gazebo>
  <collision>
    <origin xyz="-0.07 0.080468 -0.09" rpy="0 0 0"/>
    <geometry>
      <mesh filename="package://myrobot_description/meshes/right_ultrasonic_1.stl" scale="0.001 0.001 0.001"/>
    </geometry>
  </collision>
</link>

<link name="left_ultrasonic_1">
  <inertial>
    <origin xyz="0.0 0.0 0.010000000000000009" rpy="0 0 0"/>
    <mass value="0.1256"/>
    <inertia ixx="8e-06" iyy="2.1e-05" izz="2.1e-05" ixy="0.0" iyz="0.0" ixz="0.0"/>
  </inertial>
  <visual>
    <origin xyz="-0.07 -0.08 -0.09" rpy="0 0 0"/>
    <geometry>
      <mesh filename="package://myrobot_description/meshes/left_ultrasonic_1.stl" scale="0.001 0.001 0.001"/>
    </geometry>
    <material name="silver"/>
  </visual>
  <collision>
    <origin xyz="-0.07 -0.08 -0.09" rpy="0 0 0"/>
    <geometry>
      <mesh filename="package://myrobot_description/meshes/left_ultrasonic_1.stl" scale="0.001 0.001 0.001"/>
    </geometry>
  </collision>
</link>

<link name="camera_1">
  <inertial>
    <origin xyz="0.009999999999999995 -4.440892098500626e-18 0.0" rpy="0 0 0"/>
    <mass value="0.0628"/>
    <inertia ixx="4e-06" iyy="4e-06" izz="4e-06" ixy="0.0" iyz="0.0" ixz="0.0"/>
  </inertial>
  <visual>
    <origin xyz="-0.11 0.0 -0.05" rpy="0 0 0"/>
    <geometry>
      <mesh filename="package://myrobot_description/meshes/camera_1.stl" scale="0.001 0.001 0.001"/>
    </geometry>
    <material name="silver"/>
  </visual>
  <collision>
    <origin xyz="-0.11 0.0 -0.05" rpy="0 0 0"/>
    <geometry>
      <mesh filename="package://myrobot_description/meshes/camera_1.stl" scale="0.001 0.001 0.001"/>
    </geometry>
  </collision>
</link>

<joint name="Revolute 1" type="continuous">
  <origin xyz="0.0 -0.1 0.055" rpy="0 0 0"/>
  <parent link="base_link"/>
  <child link="right_wheel_1"/>
  <axis xyz="0.0 1.0 0.0"/>
</joint>

<joint name="Revolute 2" type="continuous">
  <origin xyz="0.0 0.1 0.055" rpy="0 0 0"/>
  <parent link="base_link"/>
  <child link="left_wheel_1"/>
  <axis xyz="0.0 1.0 0.0"/>
</joint>

<joint name="Rigid 3" type="fixed">
  <origin xyz="0.05 0.0 0.115" rpy="0 0 0"/>
  <parent link="base_link"/>
  <child link="lidar_1"/>
</joint>

<joint name="Rigid 4" type="fixed">
  <origin xyz="0.07 -0.080468 0.09" rpy="0 0 0"/>
  <parent link="base_link"/>
  <child link="right_ultrasonic_1"/>
</joint>

<joint name="Rigid 5" type="fixed">
  <origin xyz="0.07 0.08 0.09" rpy="0 0 0"/>
  <parent link="base_link"/>
  <child link="left_ultrasonic_1"/>
</joint>

<joint name="Rigid 6" type="fixed">
  <origin xyz="0.11 0.0 0.05" rpy="0 0 0"/>
  <parent link="base_link"/>
  <child link="camera_1"/>
</joint>

</robot>
